[2025-06-12 14:04:45 +0100] [11530] [INFO] Starting gunicorn 20.1.0
[2025-06-12 14:04:45 +0100] [11530] [INFO] Listening at: http://0.0.0.0:4000 (11530)
[2025-06-12 14:04:45 +0100] [11530] [INFO] Using worker: sync
[2025-06-12 14:04:45 +0100] [11532] [INFO] Booting worker with pid: 11532
[2025-06-12 14:04:45 +0100] [11532] [ERROR] Exception in worker process
Traceback (most recent call last):
  File "/home/justin_the_terrible/Documents/Lab_2/rpi-cd-tutorial/flask-env/lib/python3.11/site-packages/gunicorn/arbiter.py", line 589, in spawn_worker
    worker.init_process()
  File "/home/justin_the_terrible/Documents/Lab_2/rpi-cd-tutorial/flask-env/lib/python3.11/site-packages/gunicorn/workers/base.py", line 134, in init_process
    self.load_wsgi()
  File "/home/justin_the_terrible/Documents/Lab_2/rpi-cd-tutorial/flask-env/lib/python3.11/site-packages/gunicorn/workers/base.py", line 146, in load_wsgi
    self.wsgi = self.app.wsgi()
                ^^^^^^^^^^^^^^^
  File "/home/justin_the_terrible/Documents/Lab_2/rpi-cd-tutorial/flask-env/lib/python3.11/site-packages/gunicorn/app/base.py", line 67, in wsgi
    self.callable = self.load()
                    ^^^^^^^^^^^
  File "/home/justin_the_terrible/Documents/Lab_2/rpi-cd-tutorial/flask-env/lib/python3.11/site-packages/gunicorn/app/wsgiapp.py", line 58, in load
    return self.load_wsgiapp()
           ^^^^^^^^^^^^^^^^^^^
  File "/home/justin_the_terrible/Documents/Lab_2/rpi-cd-tutorial/flask-env/lib/python3.11/site-packages/gunicorn/app/wsgiapp.py", line 48, in load_wsgiapp
    return util.import_app(self.app_uri)
           ^^^^^^^^^^^^^^^^^^^^^^^^^^^^^
  File "/home/justin_the_terrible/Documents/Lab_2/rpi-cd-tutorial/flask-env/lib/python3.11/site-packages/gunicorn/util.py", line 359, in import_app
    mod = importlib.import_module(module)
          ^^^^^^^^^^^^^^^^^^^^^^^^^^^^^^^
  File "/usr/lib/python3.11/importlib/__init__.py", line 126, in import_module
    return _bootstrap._gcd_import(name[level:], package, level)
           ^^^^^^^^^^^^^^^^^^^^^^^^^^^^^^^^^^^^^^^^^^^^^^^^^^^^
  File "<frozen importlib._bootstrap>", line 1206, in _gcd_import
  File "<frozen importlib._bootstrap>", line 1178, in _find_and_load
  File "<frozen importlib._bootstrap>", line 1149, in _find_and_load_unlocked
  File "<frozen importlib._bootstrap>", line 690, in _load_unlocked
  File "<frozen importlib._bootstrap_external>", line 940, in exec_module
  File "<frozen importlib._bootstrap>", line 241, in _call_with_frames_removed
  File "/home/justin_the_terrible/Documents/Lab_2/rpi-cd-tutorial/app.py", line 1, in <module>
    from flask import Flask
  File "/home/justin_the_terrible/Documents/Lab_2/rpi-cd-tutorial/flask-env/lib/python3.11/site-packages/flask/__init__.py", line 7, in <module>
    from .app import Flask as Flask
  File "/home/justin_the_terrible/Documents/Lab_2/rpi-cd-tutorial/flask-env/lib/python3.11/site-packages/flask/app.py", line 28, in <module>
    from . import cli
  File "/home/justin_the_terrible/Documents/Lab_2/rpi-cd-tutorial/flask-env/lib/python3.11/site-packages/flask/cli.py", line 18, in <module>
    from .helpers import get_debug_flag
  File "/home/justin_the_terrible/Documents/Lab_2/rpi-cd-tutorial/flask-env/lib/python3.11/site-packages/flask/helpers.py", line 16, in <module>
    from werkzeug.urls import url_quote
ImportError: cannot import name 'url_quote' from 'werkzeug.urls' (/home/justin_the_terrible/Documents/Lab_2/rpi-cd-tutorial/flask-env/lib/python3.11/site-packages/werkzeug/urls.py)
[2025-06-12 14:04:45 +0100] [11532] [INFO] Worker exiting (pid: 11532)
[2025-06-12 14:04:45 +0100] [11530] [INFO] Shutting down: Master
[2025-06-12 14:04:45 +0100] [11530] [INFO] Reason: Worker failed to boot.
